Traceback (most recent call last):
  File "/usr/local/bin/compress.py", line 125, in <module>
    results[compressor][level].append(f.result())
                                      ^^^^^^^^^^
  File "/usr/lib/python3.12/concurrent/futures/_base.py", line 456, in result
    return self.__get_result()
           ^^^^^^^^^^^^^^^^^^^
  File "/usr/lib/python3.12/concurrent/futures/_base.py", line 401, in __get_result
    raise self._exception
concurrent.futures.process.BrokenProcessPool: A process in the process pool was terminated abruptly while the future was running or pending.
concurrent.futures.process._RemoteTraceback: 
"""
Traceback (most recent call last):
  File "/usr/lib/python3.12/concurrent/futures/process.py", line 263, in _process_worker
    r = call_item.fn(*call_item.args, **call_item.kwargs)
        ^^^^^^^^^^^^^^^^^^^^^^^^^^^^^^^^^^^^^^^^^^^^^^^^^
  File "/usr/local/bin/compress.py", line 97, in measure
    compressed_data = TASKS[compressor]["compress"](level, threads, extra_args)
                      ^^^^^^^^^^^^^^^^^^^^^^^^^^^^^^^^^^^^^^^^^^^^^^^^^^^^^^^^^
  File "/usr/local/bin/compress.py", line 46, in <lambda>
    "compress": lambda level, threads, kwargs: lzma.compress(DATA, preset=level),
                                               ^^^^^^^^^^^^^^^^^^^^^^^^^^^^^^^^^
  File "/usr/lib/python3.12/lzma.py", line 327, in compress
    comp = LZMACompressor(format, check, preset, filters)
           ^^^^^^^^^^^^^^^^^^^^^^^^^^^^^^^^^^^^^^^^^^^^^^
MemoryError
"""

The above exception was the direct cause of the following exception:

Traceback (most recent call last):
  File "/usr/local/bin/compress.py", line 125, in <module>
    results[compressor][level].append(f.result())
                                      ^^^^^^^^^^
  File "/usr/lib/python3.12/concurrent/futures/_base.py", line 456, in result
    return self.__get_result()
           ^^^^^^^^^^^^^^^^^^^
  File "/usr/lib/python3.12/concurrent/futures/_base.py", line 401, in __get_result
    raise self._exception
MemoryError
Traceback (most recent call last):
  File "/usr/local/bin/compress.py", line 125, in <module>
    results[compressor][level].append(f.result())
                                      ^^^^^^^^^^
  File "/usr/lib/python3.12/concurrent/futures/_base.py", line 456, in result
    return self.__get_result()
           ^^^^^^^^^^^^^^^^^^^
  File "/usr/lib/python3.12/concurrent/futures/_base.py", line 401, in __get_result
    raise self._exception
concurrent.futures.process.BrokenProcessPool: A process in the process pool was terminated abruptly while the future was running or pending.
Traceback (most recent call last):
  File "/usr/local/bin/compress.py", line 125, in <module>
    results[compressor][level].append(f.result())
                                      ^^^^^^^^^^
  File "/usr/lib/python3.12/concurrent/futures/_base.py", line 456, in result
    return self.__get_result()
           ^^^^^^^^^^^^^^^^^^^
  File "/usr/lib/python3.12/concurrent/futures/_base.py", line 401, in __get_result
    raise self._exception
concurrent.futures.process.BrokenProcessPool: A process in the process pool was terminated abruptly while the future was running or pending.
Traceback (most recent call last):
  File "/usr/local/bin/compress.py", line 125, in <module>
    results[compressor][level].append(f.result())
                                      ^^^^^^^^^^
  File "/usr/lib/python3.12/concurrent/futures/_base.py", line 456, in result
    return self.__get_result()
           ^^^^^^^^^^^^^^^^^^^
  File "/usr/lib/python3.12/concurrent/futures/_base.py", line 401, in __get_result
    raise self._exception
concurrent.futures.process.BrokenProcessPool: A process in the process pool was terminated abruptly while the future was running or pending.
Traceback (most recent call last):
  File "/usr/local/bin/compress.py", line 125, in <module>
    results[compressor][level].append(f.result())
                                      ^^^^^^^^^^
  File "/usr/lib/python3.12/concurrent/futures/_base.py", line 456, in result
    return self.__get_result()
           ^^^^^^^^^^^^^^^^^^^
  File "/usr/lib/python3.12/concurrent/futures/_base.py", line 401, in __get_result
    raise self._exception
concurrent.futures.process.BrokenProcessPool: A process in the process pool was terminated abruptly while the future was running or pending.
Traceback (most recent call last):
  File "/usr/local/bin/compress.py", line 125, in <module>
    results[compressor][level].append(f.result())
                                      ^^^^^^^^^^
  File "/usr/lib/python3.12/concurrent/futures/_base.py", line 456, in result
    return self.__get_result()
           ^^^^^^^^^^^^^^^^^^^
  File "/usr/lib/python3.12/concurrent/futures/_base.py", line 401, in __get_result
    raise self._exception
concurrent.futures.process.BrokenProcessPool: A process in the process pool was terminated abruptly while the future was running or pending.
Traceback (most recent call last):
  File "/usr/local/bin/compress.py", line 125, in <module>
    results[compressor][level].append(f.result())
                                      ^^^^^^^^^^
  File "/usr/lib/python3.12/concurrent/futures/_base.py", line 456, in result
    return self.__get_result()
           ^^^^^^^^^^^^^^^^^^^
  File "/usr/lib/python3.12/concurrent/futures/_base.py", line 401, in __get_result
    raise self._exception
concurrent.futures.process.BrokenProcessPool: A process in the process pool was terminated abruptly while the future was running or pending.
Traceback (most recent call last):
  File "/usr/local/bin/compress.py", line 125, in <module>
    results[compressor][level].append(f.result())
                                      ^^^^^^^^^^
  File "/usr/lib/python3.12/concurrent/futures/_base.py", line 456, in result
    return self.__get_result()
           ^^^^^^^^^^^^^^^^^^^
  File "/usr/lib/python3.12/concurrent/futures/_base.py", line 401, in __get_result
    raise self._exception
concurrent.futures.process.BrokenProcessPool: A process in the process pool was terminated abruptly while the future was running or pending.
Traceback (most recent call last):
  File "/usr/local/bin/compress.py", line 125, in <module>
    results[compressor][level].append(f.result())
                                      ^^^^^^^^^^
  File "/usr/lib/python3.12/concurrent/futures/_base.py", line 456, in result
    return self.__get_result()
           ^^^^^^^^^^^^^^^^^^^
  File "/usr/lib/python3.12/concurrent/futures/_base.py", line 401, in __get_result
    raise self._exception
concurrent.futures.process.BrokenProcessPool: A process in the process pool was terminated abruptly while the future was running or pending.
