{"start":"2025-10-07T04:22:17.945296","end":"2025-10-07T04:22:17.945296","exit_code":-1,"error_msg":"an unhandled error occurred: python inline source runtime error: No row was found when one was required\nTraceback (most recent call last):\n  File \"/venv/inspector/lib/python3.12/site-packages/pulumi/automation/_server.py\", line 83, in run\n    loop.run_until_complete(run_in_stack(self.program))\n  File \"/usr/local/lib/python3.12/asyncio/base_events.py\", line 691, in run_until_complete\n    return future.result()\n           ^^^^^^^^^^^^^^^\n  File \"/venv/inspector/lib/python3.12/site-packages/pulumi/runtime/stack.py\", line 143, in run_in_stack\n    await run_pulumi_func(run)\n  File \"/venv/inspector/lib/python3.12/site-packages/pulumi/runtime/stack.py\", line 53, in run_pulumi_func\n    func()\n  File \"/venv/inspector/lib/python3.12/site-packages/pulumi/runtime/stack.py\", line 140, in run\n    Stack(func)\n  File \"/venv/inspector/lib/python3.12/site-packages/pulumi/runtime/stack.py\", line 169, in __init__\n    awaitable = func()\n                ^^^^^^\n  File \"/venv/inspector/lib/python3.12/site-packages/sc_runner/runner.py\", line 79, in pulumi_program\n    return resource_f(**resource_opts)\n           ^^^^^^^^^^^^^^^^^^^^^^^^^^^\n  File \"/venv/inspector/lib/python3.12/site-packages/sc_runner/resources/aws.py\", line 86, in resources_aws\n    arch = data.server_cpu_architecture(\"aws\", instance).lower().replace(\"i386\", \"x86_64\")\n           ^^^^^^^^^^^^^^^^^^^^^^^^^^^^^^^^^^^^^^^^^^^^^\n  File \"/venv/inspector/lib/python3.12/site-packages/sc_runner/data.py\", line 40, in server_cpu_architecture\n    return session.exec(select(Server.cpu_architecture).where(Server.vendor_id == vendor).where(Server.api_reference == server)).one().value\n           ^^^^^^^^^^^^^^^^^^^^^^^^^^^^^^^^^^^^^^^^^^^^^^^^^^^^^^^^^^^^^^^^^^^^^^^^^^^^^^^^^^^^^^^^^^^^^^^^^^^^^^^^^^^^^^^^^^^^^^^^^^^\n  File \"/venv/inspector/lib/python3.12/site-packages/sqlalchemy/engine/result.py\", line 1808, in one\n    return self._only_one_row(\n           ^^^^^^^^^^^^^^^^^^^\n  File \"/venv/inspector/lib/python3.12/site-packages/sqlalchemy/engine/result.py\", line 752, in _only_one_row\n    raise exc.NoResultFound(\nsqlalchemy.exc.NoResultFound: No row was found when one was required\n\n","task_hash":"5f210f1a2dbfbab7a50d5fb6a1d7a2034445bd38","version":null,"stdout_bytes":null,"stderr_bytes":null,"outputs":[]}