{"start":"2025-04-16T07:40:03.848653","end":"2025-04-16T07:40:03.848653","exit_code":-1,"error_msg":"an unhandled error occurred: python inline source runtime error: module 'pulumi_aws.ec2' has no attribute 'InstanceRootBlockDeviceArgs'\nTraceback (most recent call last):\n  File \"/venv/inspector/lib/python3.12/site-packages/pulumi/automation/_server.py\", line 83, in run\n    loop.run_until_complete(run_in_stack(self.program))\n  File \"/usr/local/lib/python3.12/asyncio/base_events.py\", line 691, in run_until_complete\n    return future.result()\n           ^^^^^^^^^^^^^^^\n  File \"/venv/inspector/lib/python3.12/site-packages/pulumi/runtime/stack.py\", line 143, in run_in_stack\n    await run_pulumi_func(run)\n  File \"/venv/inspector/lib/python3.12/site-packages/pulumi/runtime/stack.py\", line 53, in run_pulumi_func\n    func()\n  File \"/venv/inspector/lib/python3.12/site-packages/pulumi/runtime/stack.py\", line 140, in run\n    Stack(func)\n  File \"/venv/inspector/lib/python3.12/site-packages/pulumi/runtime/stack.py\", line 169, in __init__\n    awaitable = func()\n                ^^^^^^\n  File \"/venv/inspector/lib/python3.12/site-packages/sc_runner/runner.py\", line 79, in pulumi_program\n    return resource_f(**resource_opts)\n           ^^^^^^^^^^^^^^^^^^^^^^^^^^^\n  File \"/venv/inspector/lib/python3.12/site-packages/sc_runner/resources/aws.py\", line 82, in resources_aws\n    instance_opts[\"root_block_device\"] = aws.ec2.InstanceRootBlockDeviceArgs(volume_size=disk_size)\n                                         ^^^^^^^^^^^^^^^^^^^^^^^^^^^^^^^^^^^\nAttributeError: module 'pulumi_aws.ec2' has no attribute 'InstanceRootBlockDeviceArgs'\n\n","task_hash":"e68b9a673002a9de8a75bfbedea1da52162dc897","version":null,"stdout_bytes":null,"stderr_bytes":null,"outputs":[]}