2025-04-14 08:52:33,209 - INFO - Using CPU-build of llama.cpp
2025-04-14 08:52:33,232 - INFO - Benchmarking model SmolLM-135M.Q4_K_M.gguf ...
2025-04-14 08:52:33,233 - DEBUG - Downloading model SmolLM-135M.Q4_K_M.gguf from https://huggingface.co/QuantFactory/SmolLM-135M-GGUF/resolve/main/SmolLM-135M.Q4_K_M.gguf
Process Process-2:
Traceback (most recent call last):
  File "/usr/lib/python3.10/multiprocessing/process.py", line 314, in _bootstrap
    self.run()
  File "/usr/lib/python3.10/multiprocessing/process.py", line 108, in run
    self._target(*self._args, **self._kwargs)
  File "/benchmark.py", line 157, in download_models
    urlretrieve(model_url, temp_path)
  File "/usr/lib/python3.10/urllib/request.py", line 241, in urlretrieve
    with contextlib.closing(urlopen(url, data)) as fp:
  File "/usr/lib/python3.10/urllib/request.py", line 216, in urlopen
    return opener.open(url, data, timeout)
  File "/usr/lib/python3.10/urllib/request.py", line 525, in open
    response = meth(req, response)
  File "/usr/lib/python3.10/urllib/request.py", line 634, in http_response
    response = self.parent.error(
  File "/usr/lib/python3.10/urllib/request.py", line 563, in error
    return self._call_chain(*args)
  File "/usr/lib/python3.10/urllib/request.py", line 496, in _call_chain
    result = func(*args)
  File "/usr/lib/python3.10/urllib/request.py", line 643, in http_error_default
    raise HTTPError(req.full_url, code, msg, hdrs, fp)
urllib.error.HTTPError: HTTP Error 500: Internal Server Error
2025-04-14 09:07:33,235 - ERROR - SmolLM-135M.Q4_K_M.gguf was not downloaded in time.
