{"start":"2024-08-22T14:57:42.564710","end":"2024-08-22T14:57:42.564710","exit_code":-1,"error_msg":"an unhandled error occurred: python inline source runtime error: resources_aws() got an unexpected keyword argument 'public-key'\nTraceback (most recent call last):\n  File \"/venv/inspector/lib/python3.12/site-packages/pulumi/automation/_server.py\", line 80, in run\n    loop.run_until_complete(run_in_stack(self.program))\n  File \"/usr/local/lib/python3.12/asyncio/base_events.py\", line 687, in run_until_complete\n    return future.result()\n           ^^^^^^^^^^^^^^^\n  File \"/venv/inspector/lib/python3.12/site-packages/pulumi/runtime/stack.py\", line 142, in run_in_stack\n    await run_pulumi_func(run)\n  File \"/venv/inspector/lib/python3.12/site-packages/pulumi/runtime/stack.py\", line 54, in run_pulumi_func\n    func()\n  File \"/venv/inspector/lib/python3.12/site-packages/pulumi/runtime/stack.py\", line 139, in run\n    Stack(func)\n  File \"/venv/inspector/lib/python3.12/site-packages/pulumi/runtime/stack.py\", line 168, in __init__\n    awaitable = func()\n                ^^^^^^\n  File \"/venv/inspector/lib/python3.12/site-packages/sc_runner/runner.py\", line 76, in pulumi_program\n    return resource_f(**resource_opts)\n           ^^^^^^^^^^^^^^^^^^^^^^^^^^^\nTypeError: resources_aws() got an unexpected keyword argument 'public-key'\n\n","task_hash":"88d55e56501a43832ff813c91444737e1f087958","version":null,"stdout_bytes":null,"stderr_bytes":null,"outputs":[]}